Workbook

Sheet UV
A1: U-Nr | B1: Kl,Le | C1: Nvpl Std. | D1: Wst | E1: Lehrer | F1: Fach | G1: Klasse(n) | H1: U-Gruppen | I1: Fachraum | J1: Schülergruppe | K1: Dopp.Std. | L1: Stammraum | M1: ZeilenText-2 | N1: ZeilenText | O1: Fix (X) | P1: Ignore (i) | Q1: KKK | R1: (E) | S1: Text
A2: 1093 | B2: (i) | D2: 2 | E2: L70 | F2: BI | G2: 05A | I2: RBiÜ2 | J2: BI_05A | K2: 0-1 | L2: R05a | M2: S1 Vorm. | P2: i | R2: x
A3: 151 | B3: (i) | D3: 4 | E3: L1 | F3: D | G3: 05A | K3: 1-1 | L3: R05a | M3: S1 Vorm. | P3: i | R3: x
A4: 150 | B4: (i) | D4: 5 | E4: L82 | F4: E | G4: 05A | K4: 0-2 | L4: R05a | M4: S1 Vorm. | P4: i | R4: x
A5: 152 | B5: (i) | D5: 2 | E5: L43 | F5: EK | G5: 05A | I5: REk1 | L5: R05a | M5: S1 Vorm. | P5: i | R5: x
A6: 219 | B6: (i) | D6: 1 | E6: L1 | F6: KL_Erg | G6: 05A | L6: R05a | M6: S1 Vorm. | P6: i | R6: x
A7: 154 | B7: (i) | D7: 2 | E7: L1 | F7: KU | G7: 05A | I7: RKu3 | K7: 1-1 | M7: S1 Vorm. | P7: i | R7: x
A8: 154 | B8: (i) | D8: 2 | E8: L1 | F8: KU | G8: 05A | I8: RKu3 | K8: 1-1 | M8: S1 Vorm. | P8: i | R8: x
A9: 1105 | B9: (i) | D9: 4 | E9: L33 | F9: M | G9: 05A | J9: 05A_M | K9: 0-1 | L9: R05a | M9: S1 Vorm. | P9: i | R9: x
A10: 146 | B10: (i) | D10: 1 | E10: L82 | F10: Meth ERG | G10: 05A | L10: R05a | M10: S1 Vorm. | P10: i | R10: x
A11: 147 | B11: (i) | D11: 2 | E11: L68 | F11: MU | G11: 05A | I11: RMu1 | L11: R05a | M11: S1 Vorm. | P11: i | R11: x
A12: 149 | B12: (i) | D12: 2 | E12: L78 | F12: SP | G12: 05A | I12: RSh1 | J12: 05A_SP | K12: 46023 | M12: S1 Sp Block 1 | P12: i
A13: 145 | B13: (i) | D13: 2 | E13: L40 | F13: WiPo | G13: 05A | L13: R05a | M13: S1 Vorm. | P13: i | R13: x
A14: 1727 | B14: 4, 6 | D14: 2 | E14: L82 | F14: ER | G14: 05A,05B,05C,05D | I14: ReR | M14: S1 V Block | R14: x
A15: 1727 | B15: 4, 6 | D15: 2 | E15: L22 | F15: KR | G15: 05A,05B,05C,05D | L15: R05a | M15: S1 V Block | R15: x
A16: 1727 | B16: 4, 6 | D16: 2 | E16: L72 | F16: KR | G16: 05A,05B,05C,05D | L16: R05b | M16: S1 V Block | R16: x
A17: 1727 | B17: 4, 6 | D17: 2 | E17: L23 | F17: PP | G17: 05A,05B,05C,05D | J17: PP_1 | L17: R05c | M17: S1 V Block | R17: x
A18: 1727 | B18: 4, 6 | D18: 2 | E18: L46 | F18: PP | G18: 05A,05B,05C,05D | J18: PP_2 | L18: R05d | M18: S1 V Block | R18: x
A19: 1727 | B19: 4, 6 | D19: 2 | E19: L80 | F19: PP | G19: 05A,05B,05C,05D | J19: PP_3 | L19: R10a | M19: S1 V Block | R19: x
A20: 1733 | B20: 5, 2 | D20: 1 | E20: L50 | F20: StrPr | G20: 05A,05B,05C,05D,AG7 | L20: R05d | M20: S1 V Block | O20: x
A21: 1733 | B21: 5, 2 | D21: 1 | E21: L68 | F21: StrPr | G21: 05A,05B,05C,05D,AG7 | J21: StrPr_05A_05B_05C_05D | L21: R05c | M21: S1 V Block | O21: x
A22: 113 | B22: (i) | D22: 2 | E22: L70 | F22: BI | G22: 05B | I22: RBiÜ1 | M22: S1 Vorm. | P22: i | R22: x
A23: 114 | B23: (i) | D23: 4 | E23: L80 | F23: D | G23: 05B | K23: 1-1 | L23: R05b | M23: S1 Vorm. | P23: i | R23: x
A24: 116 | B24: (i) | D24: 5 | E24: L58 | F24: E | G24: 05B | K24: 0-1 | L24: R05b | M24: S1 Vorm. | P24: i | R24: x
A25: 117 | B25: (i) | D25: 2 | E25: L63 | F25: EK | G25: 05B | I25: REk1 | L25: R05b | M25: S1 Vorm. | P25: i | R25: x
A26: 221 | B26: (i) | D26: 1 | E26: L80 | F26: KL_Erg | G26: 05B | L26: R05b | M26: S1 Vorm. | P26: i | R26: x
A27: 118 | B27: (i) | D27: 2 | E27: L52 | F27: KU | G27: 05B | I27: RKu1 | K27: 1-1 | M27: S1 Vorm. | P27: i | R27: x
A28: 118 | B28: (i) | D28: 2 | E28: L52 | F28: KU | G28: 05B | I28: RKu1 | K28: 1-1 | M28: S1 Vorm. | P28: i | R28: x
A29: 119 | B29: (i) | D29: 4 | E29: L56 | F29: M | G29: 05B | K29: 0-1 | L29: R05b | M29: S1 Vorm. | P29: i | R29: x
A30: 143 | B30: (i) | D30: 1 | E30: L80 | F30: Meth ERG | G30: 05B | L30: R05b | M30: S1 Vorm. | P30: i | R30: x
A31: 120 | B31: (i) | D31: 2 | E31: L46 | F31: MU | G31: 05B | I31: RMu1 | M31: S1 Vorm. | P31: i | R31: x
A32: 1700 | B32: (i) | D32: 2 | E32: L74 | F32: SP | G32: 05B | I32: RSh1 | K32: 46023 | M32: S1 Sp Block 1 | P32: i
A33: 121 | B33: (i) | D33: 2 | E33: L12 | F33: WiPo | G33: 05B | L33: R05b | M33: S1 Vorm. | P33: i | R33: x
A34: 103 | B34: (i) | D34: 2 | E34: L70 | F34: BI | G34: 05C | I34: RBiÜ1 | M34: S1 Vorm. | P34: i | R34: x
A35: 104 | B35: (i) | D35: 4 | E35: L22 | F35: D | G35: 05C | K35: 1-1 | L35: R05c | M35: S1 Vorm. | P35: i | R35: x
A36: 157 | B36: (i) | D36: 5 | E36: L40 | F36: E | G36: 05C | K36: 0-1 | L36: R05c | M36: S1 Vorm. | P36: i | R36: x
A37: 105 | B37: (i) | D37: 2 | E37: L43 | F37: EK | G37: 05C | I37: REk1 | L37: R05c | M37: S1 Vorm. | P37: i | R37: x
A38: 220 | B38: (i) | D38: 1 | E38: L22 | F38: KL_Erg | G38: 05C | L38: R05c | M38: S1 Vorm. | P38: i | R38: x
A39: 159 | B39: (i) | D39: 2 | E39: L77 | F39: KU | G39: 05C | I39: RKu3 | K39: 1-1 | M39: S1 Vorm. | P39: i | R39: x
A40: 159 | B40: (i) | D40: 2 | E40: L77 | F40: KU | G40: 05C | I40: RKu3 | K40: 1-1 | M40: S1 Vorm. | P40: i | R40: x
...

Sheet LKue
A1: Originalname | B1: KÃ¼rzel
B2: L1
B3: L2
B4: L3
B5: L4
B6: L5
B7: L6
B8: L7
B9: L8
B10: L9
B11: L10
B12: L11
B13: L12
... B95: L94
A96: Z12_1-8 | B96: L95
A97: Z12_8-9 | B97: L96
A98: Z5a-e_7 | B98: L97
A99: Z6a-e_7 | B99: L98
A100: Z7a-e_7 | B100: L99
A101: Z8a-e_7 | B101: L100
A102: Z9a_7 | B102: L101
A103: Z9b_7 | B103: L102
A104: Z9c_7 | B104: L103
A105: Z9d_7 | B105: L104
A106: Z9e_7 | B106: L105

Sheet PM
A1: Zeitlimitsekunden für solver | B1: 10
A3: Anzahl der Lösungen ohne Tausch | B3: 2
A4: Anzahl der Lösungen mit Tausch | B4: 0
A5: NichtFreieTage z.B. Mo,Fr eingeben | B5: Mi | C5: Tage können trotzdem belegt werden, werden aber indirekt bestraft
A6: frühe Doppelstunden | B6: 5 | E6: Qualität = frühe Doppelstunden × 1
A7: Strafe späte Doppelstunden | B7: 10 | E7: - späte Doppelstunden × 5
A8: Strafe späte pädagogische Einheiten | B8: 10 | E8: - schlechte päd. Einheiten × 5
A9: Belohnung für extra freie Tage an bevorzugtem Wochentag | B9: 1 | C9: Belohnung für extra freie Tage (nur falls nicht an oben genannten Wochentag) | E9: + freie Lehrertage × 2
A10: zuviele späte LK Stunden | B10: 10 | C10: mehr als 2 nach Stunde 5
A12: Hohlstundenstrafe | B12: 1
A13: Doppelhohlstundenstrafe | B13: 10
A14: Dreifachhohlstundenstrafe | B14: 200
A15: Strafe Einzelstunde | B15: 10
A16: Strafe Std.folge | B16: 5
A20: große Pause 1 | B20: 2-3
A21: große Pause 2 | B21: 4-5
A22: große Pause 3 | B22: 6-7
A24: Verbot Doppelstunde auf 6,7 oder 7,8 oder 8,9 | B24: nein
A26: Verbot -2 -Verletzungen | B26: nein
A27: Strafe -2 -Verletzungen | B27: 10

Sheet FT
A1: =StD!B1 -> Name | B1: Anzahl zusätzliche FT | C1: Gewichtung
A2: =StD!B2 -> L1 | B2: 1 | C2: -2
A3: =StD!B3 -> L2 | C3: -2
A4: =StD!B4 -> L3 | B4: 1 | C4: -2
A5: =StD!B5 -> L4 | B5: 1 | C5: -2
A6: =StD!B6 -> L5 | C6: -2
A7: =StD!B7 -> L6 | C7: -2
A8: =StD!B8 -> L7 | B8: 1 | C8: -2
A9: =StD!B9 -> L8 | C9: -2
A10: =StD!B10 -> L9 | C10: -2
A11: =StD!B11 -> L10 | C11: -2
A12: =StD!B12 -> L11 | C12: -2
A13: =StD!B13 -> L12 | C13: -2
A14: =StD!B14 -> L13 | B14: 1 | C14: -2
A15: =StD!B15 -> L14 | C15: -2
A16: =StD!B16 -> L15 | B16: 2 | C16: -2
A17: =StD!B17 -> L16 | C17: -2
A18: =StD!B18 -> L17 | C18: -2
A19: =StD!B19 -> L18 | B19: 1 | C19: -2
A20: =StD!B20 -> L19 | C20: -2
A21: =StD!B21 -> L20 | B21: 1 | C21: -2
A22: =StD!B22 -> L21 | C22: -2
A23: =StD!B23 -> L22 | B23: 2 | C23: -2
A24: =StD!B24 -> L23 | C24: -2
A25: =StD!B25 -> 0 | C25: -2
A26: =StD!B26 -> L24 | B26: 2 | C26: -2
A27: =StD!B27 -> L25 | C27: -2
A28: =StD!B28 -> L27 | B28: 1 | C28: -2
A29: =StD!B29 -> L28 | B29: 1 | C29: -2
A30: =StD!B30 -> 0 | C30: -2
A31: =StD!B31 -> L29 | C31: -2
A32: =StD!B32 -> L30 | C32: -2
A33: =StD!B33 -> L31 | C33: -2
A34: =StD!B34 -> L32 | B34: 1 | C34: -2
A35: =StD!B35 -> L33 | C35: -2
A36: =StD!B36 -> L34 | B36: 1 | C36: -2
A37: =StD!B37 -> L35 | C37: -2
A38: =StD!B38 -> L36 | C38: -2
A39: =StD!B39 -> L37 | C39: -2
A40: =StD!B40 -> L38 | C40: -2
...

Sheet Fix UNrn
A1: WTag | B1: Stunde | C1: späte S2 und GD Fixierungen | I1: Q2
A2: Mo | B2: 1 | C2: 232
A3: Mo | B3: 2
A4: Mo | B4: 3
A5: Mo | B5: 4
A6: Mo | B6: 5
A7: Mo | B7: 6
A8: Mo | B8: 7
A9: Mo | B9: 8 | C9: 1339 | D9: 1740 | E9: 1092 | F9: 1739 | G9: 1566
A10: Mo | B10: 9 | C10: 1339 | D10: 1740 | E10: 1092 | F10: 1739 | G10: 1566
A11: Mo | B11: 10 | H11: 906
A12: Mo | B12: 11
A13: Di | B13: 1 | C13: 83 | D13: 1211
A14: Di | B14: 2
A15: Di | B15: 3
A16: Di | B16: 4
A17: Di | B17: 5
A18: Di | B18: 6
A19: Di | B19: 7 | D19: 1733
A20: Di | B20: 8 | C20: 1341 | E20: 904 | F20: 1462 | G20: 1650
A21: Di | B21: 9 | C21: 1341 | E21: 904 | F21: 1462 | G21: 1650
A22: Di | B22: 10 | H22: 908
A23: Di | B23: 11
A24: Mi | B24: 1 | C24: 83 | D24: 1727
A25: Mi | B25: 2
A26: Mi | B26: 3
A27: Mi | B27: 4
A28: Mi | B28: 5
A29: Mi | B29: 6
A30: Mi | B30: 7
A31: Mi | B31: 8
A32: Mi | B32: 9
A33: Mi | B33: 10
A34: Mi | B34: 11
A35: Do | B35: 1 | C35: 156
A36: Do | B36: 2
A37: Do | B37: 3
A38: Do | B38: 4
A39: Do | B39: 5
A40: Do | B40: 6
...

Sheet Fix spät+GD+Cho+VPL
A1: WTag | B1: Stunde | C1: späte S2 und GD Fixierungen | I1: Q2 | K1: Q1 | M1: EF
A2: Mo | B2: 1 | C2: 232
A3: Mo | B3: 2
A4: Mo | B4: 3
A5: Mo | B5: 4
A6: Mo | B6: 5
A7: Mo | B7: 6
A8: Mo | B8: 7
A9: Mo | B9: 8 | C9: 1339 | D9: 1740 | E9: 1092 | F9: 1739 | G9: 1566
A10: Mo | B10: 9 | C10: 1339 | D10: 1740 | E10: 1092 | F10: 1739 | G10: 1566
A11: Mo | B11: 10 | H11: 906
A12: Mo | B12: 11
A13: Di | B13: 1 | C13: 83 | D13: 1211
A14: Di | B14: 2
A15: Di | B15: 3
A16: Di | B16: 4
A17: Di | B17: 5
A18: Di | B18: 6
A19: Di | B19: 7 | D19: 1733
A20: Di | B20: 8 | C20: 1341 | E20: 904 | F20: 1462 | G20: 1650
A21: Di | B21: 9 | C21: 1341 | E21: 904 | F21: 1462 | G21: 1650
A22: Di | B22: 10 | H22: 908
A23: Di | B23: 11
A24: Mi | B24: 1 | C24: 83 | D24: 1727
A25: Mi | B25: 2
A26: Mi | B26: 3
A27: Mi | B27: 4
A28: Mi | B28: 5
A29: Mi | B29: 6
A30: Mi | B30: 7
A31: Mi | B31: 8
A32: Mi | B32: 9
A33: Mi | B33: 10
A34: Mi | B34: 11
A35: Do | B35: 1 | C35: 156
A36: Do | B36: 2
A37: Do | B37: 3
A38: Do | B38: 4
A39: Do | B39: 5
A40: Do | B40: 6
...

Sheet Plan
A1: WTag | B1: Stunde | C1: späte S2 und GD Fixierungen
A2: Mo | B2: 1 | C2: 232 | D2: 1367 | E2: 1400 | F2: 1505
A3: Mo | B3: 2 | C3: 1367 | D3: 1400 | E3: 1505
A4: Mo | B4: 3 | C4: 1327 | D4: 1385 | E4: 1475 | F4: 154
A5: Mo | B5: 4 | C5: 1327 | D5: 1385 | E5: 1475 | F5: 154
A6: Mo | B6: 5 | C6: 1357 | D6: 1432 | E6: 1517
A7: Mo | B7: 6 | C7: 1325 | D7: 1426 | E7: 1473
A8: Mo | B8: 7 | C8: 1325 | D8: 1396 | E8: 1473
A9: Mo | B9: 8 | C9: 1339 | D9: 1740 | E9: 1092 | F9: 1739 | G9: 1566
A10: Mo | B10: 9 | C10: 1339 | D10: 1740 | E10: 1092 | F10: 1739 | G10: 1566
A11: Mo | B11: 10 | H11: 906
A12: Mo | B12: 11
A13: Di | B13: 1 | C13: 83 | D13: 1211 | E13: 1359 | F13: 1449 | G13: 1478
A14: Di | B14: 2 | C14: 1311 | D14: 1429 | E14: 1463
A15: Di | B15: 3 | C15: 1311 | D15: 1429 | E15: 1463 | F15: 1727 | G15: 24
A16: Di | B16: 4 | C16: 1355 | D16: 1380 | E16: 1488 | F16: 24
A17: Di | B17: 5 | C17: 1313 | D17: 1435 | E17: 1555 | F17: 223
A18: Di | B18: 6 | C18: 1313 | D18: 1435 | E18: 1498 | F18: 223
A19: Di | B19: 7 | D19: 1733 | E19: 1363 | F19: 1403 | G19: 1525
A20: Di | B20: 8 | C20: 1341 | E20: 904 | F20: 1462 | G20: 1650
A21: Di | B21: 9 | C21: 1341 | E21: 904 | F21: 1462 | G21: 1650
A22: Di | B22: 10 | H22: 908
A23: Di | B23: 11
A24: Mi | B24: 1 | C24: 83 | D24: 1727 | E24: 1319 | F24: 1384 | G24: 1489
A25: Mi | B25: 2 | C25: 1319 | D25: 1384 | E25: 1489
A26: Mi | B26: 3 | C26: 1351 | D26: 1393 | E26: 1499 | F26: 1211
A27: Mi | B27: 4 | C27: 1315 | D27: 1393 | E27: 1572
A28: Mi | B28: 5 | C28: 1315 | D28: 1406 | E28: 1572 | F28: 1110 | G28: 1193 | H28: 3
A29: Mi | B29: 6 | C29: 1331 | D29: 1406 | E29: 1468 | F29: 1110 | G29: 1193 | H29: 3
A30: Mi | B30: 7 | C30: 1321 | D30: 1440 | E30: 1480
A31: Mi | B31: 8 | C31: 1321
A32: Mi | B32: 9
A33: Mi | B33: 10
A34: Mi | B34: 11
A35: Do | B35: 1 | C35: 156 | D35: 1375 | E35: 1411 | F35: 1510 | G35: 110
A36: Do | B36: 2 | C36: 1311 | D36: 1388 | E36: 1494 | F36: 110 | G36: 18
A37: Do | B37: 3 | C37: 1311 | D37: 1392 | E37: 1494 | F37: 118 | G37: 18
A38: Do | B38: 4 | C38: 1329 | D38: 1392 | E38: 1483 | F38: 159 | G38: 118
A39: Do | B39: 5 | C39: 1329 | D39: 1445 | E39: 1483 | F39: 1181 | G39: 159
A40: Do | B40: 6 | C40: 1347 | D40: 1445 | E40: 1464 | F40: 1181
...

Sheet B-Unr-Plan
A1: WTag | B1: Stunde | C1: UNr
A2: Mo | B2: 1 | C2: 1351
A3: Mo | B3: 2 | C3: 1373
A4: Mo | B4: 3 | C4: 1321
A5: Mo | B5: 4 | C5: 1321
A6: Mo | B6: 5 | C6: 1327
A7: Mo | B7: 6 | C7: 1327
A8: Mo | B8: 7 | C8: 1347
A9: Mo | B9: 8 | C9: 1339 | D9: 1740
A10: Mo | B10: 9 | C10: 1339
A11: Mo | B11: 10
A12: Mo | B12: 11
A13: Di | B13: 1 | C13: 1359 | D13: 1211
A14: Di | B14: 2 | C14: 1331
A15: Di | B15: 3 | C15: 1361
A16: Di | B16: 4 | C16: 1313
A17: Di | B17: 5 | C17: 1313
A18: Di | B18: 6 | C18: 1363
A19: Di | B19: 7 | C19: 1355 | D19: 1733
A20: Di | B20: 8 | C20: 1341
A21: Di | B21: 9 | C21: 1341
A22: Di | B22: 10
A23: Di | B23: 11
A24: Mi | B24: 1 | C24: 1313 | D24: 1727
A25: Mi | B25: 2 | C25: 1313
A26: Mi | B26: 3 | C26: 1319
A27: Mi | B27: 4 | C27: 1319
A28: Mi | B28: 5 | C28: 1325
A29: Mi | B29: 6 | C29: 1325
A30: Mi | B30: 7 | C30: 1357
A31: Mi | B31: 8
A32: Mi | B32: 9
A33: Mi | B33: 10
A34: Mi | B34: 11
A35: Do | B35: 1 | C35: 1329
A36: Do | B36: 2 | C36: 1329
A37: Do | B37: 3 | C37: 1315
A38: Do | B38: 4 | C38: 1315
A39: Do | B39: 5 | C39: 1311 | D39: 1727
A40: Do | B40: 6 | C40: 1311 | D40: 1211
...

Sheet FGR
A1: Bio | B1: 4
A2: Chemie | B2: 2
A3: Kunst | B3: 3
A4: Musik | B4: 2
A5: Physik | B5: 3
A6: Sport | B6: 3
A7: Informatik | B7: 2

Sheet StD
B1: Name | C1: Soll/Woche | D1: Anrechnungen | E1: Wert Unt. | F1: Ist-Soll | G1: Pers.Nr | H1: Status | I1: Geburtsdatum | J1: Std.Folge | K1: Max.Verw. | L1: Std./Tag | M1: HohlStd. soll | N1: Ist (Wert =) | O1: N.Druck. (N) | P1: ( _ ) | Q1: Sperr.
B2: L1 | C2: 16 | D2: -0.597 | E2: 16.65 | F2: 0.053 | H2: a | J2: 6 | K2: 7 | L2: 46175 | M2: 46082 | N2: 16.053 | Q2: 0
B3: L2 | C3: 25.5 | E3: 23.5 | F3: -2 | K3: 0 | N3: 23.5 | Q3: 0
B4: L3 | C4: 20 | D4: 2 | E4: 18 | F4: 0 | H4: a | J4: 6 | K4: 7 | L4: 46175 | M4: 46114 | N4: 20 | Q4: 0
B5: L4 | C5: 18 | D5: 7.866 | E5: 9 | F5: -1.134 | H5: a | J5: 6 | K5: 7 | L5: 46175 | M5: 46082 | N5: 16.866 | Q5: 0
B6: L5 | C6: 25.5 | D6: 0.874 | E6: 24 | F6: -0.626 | H6: v | J6: 6 | K6: 7 | L6: 46175 | M6: 46114 | N6: 24.874 | Q6: 0
B7: L6 | C7: 25.5 | D7: 1.77 | E7: 23 | F7: -0.73 | H7: v | J7: 6 | K7: 7 | L7: 46175 | M7: 46114 | N7: 24.77 | Q7: 0
B8: L7 | C8: 17 | D8: 1.588 | E8: 15 | F8: -0.412 | H8: a | J8: 6 | K8: 7 | L8: 46175 | M8: 46054 | N8: 16.588 | Q8: 0
B9: L8 | C9: 25 | D9: 3.081 | E9: 22 | F9: 0.081 | H9: a | J9: 6 | K9: 7 | L9: 46175 | M9: 46114 | N9: 25.081 | Q9: 0
B10: L9 | E10: 0 | F10: 0 | H10: v | J10: 6 | K10: 7 | L10: 46175 | M10: 46114 | N10: 0 | O10: x | Q10: 0
B11: L10 | C11: 25.5 | D11: 1.377 | E11: 24 | F11: -0.123 | H11: a | J11: 6 | K11: 7 | L11: 46175 | M11: 46114 | N11: 25.377 | Q11: 0
B12: L11 | C12: 25.5 | D12: 10.121 | E12: 14 | F12: -1.379 | H12: v | J12: 6 | K12: 7 | L12: 46175 | M12: 46114 | N12: 24.121 | Q12: 0
B13: L12 | C13: 25.5 | D13: 0.969 | E13: 25 | F13: 0.469 | H13: v | J13: 6 | K13: 7 | L13: 46175 | M13: 46054 | N13: 25.969 | Q13: 0
B14: L13 | C14: 20 | D14: 2.839 | E14: 18 | F14: 0.839 | H14: a | J14: 6 | K14: 7 | L14: 46175 | M14: 46114 | N14: 20.839 | Q14: 0
B15: L14 | C15: 25.5 | D15: 4.982 | E15: 21 | F15: 0.482 | H15: v | J15: 6 | K15: 7 | L15: 46175 | M15: 46114 | N15: 25.982 | Q15: 0
B16: L15 | C16: 7 | D16: -0.595 | E16: 7 | F16: -0.595 | H16: a | J16: 6 | K16: 7 | L16: 46175 | M16: 46054 | N16: 6.405 | Q16: 0
B17: L16 | C17: 25.5 | D17: 0.952 | E17: 24 | F17: -0.548 | H17: v | J17: 6 | K17: 7 | L17: 46175 | M17: 46114 | N17: 24.952 | Q17: 0
B18: L17 | C18: 18 | D18: 0.471 | E18: 18 | F18: 0.471 | H18: a | J18: 6 | K18: 7 | L18: 46175 | M18: 46114 | N18: 18.471 | Q18: 0
B19: L18 | C19: 19 | D19: 4.053 | E19: 14.7 | F19: -0.247 | H19: a | J19: 6 | K19: 7 | L19: 46175 | M19: 46082 | N19: 18.753 | Q19: 0
B20: L19 | C20: 25.5 | D20: 19.01 | E20: 8 | F20: 1.51 | H20: v | J20: 6 | K20: 7 | M20: 43101 | N20: 27.01 | Q20: 0
B21: L20 | C21: 19.5 | D21: 3.17 | E21: 17 | F21: 0.67 | H21: a | J21: 6 | K21: 7 | L21: 46175 | M21: 46082 | N21: 20.17 | Q21: 0
B22: L21 | C22: 9 | E22: 9 | F22: 0 | K22: 0 | L22: 0-6 | N22: 9 | Q22: 0
B23: L22 | C23: 14 | D23: -0.377 | E23: 14.65 | F23: 0.273 | H23: a | J23: 6 | K23: 7 | L23: 46175 | M23: 46054 | N23: 14.273 | Q23: 0
B24: L23 | C24: 15 | D24: 6.715 | E24: 9 | F24: 0.715 | H24: a | J24: 6 | K24: 7 | L24: 46175 | M24: 46082 | N24: 15.715 | Q24: 0
D25: -0.433 | E25: 0 | F25: -0.433 | J25: 6 | K25: 7 | L25: 46175 | M25: 46114 | N25: -0.433 | O25: x | Q25: 0
B26: L24 | C26: 13 | D26: -0.729 | E26: 14 | F26: 0.271 | H26: a | J26: 6 | K26: 7 | L26: 46175 | M26: 46054 | N26: 13.271 | Q26: 0
B27: L25 | C27: 23 | D27: 3.853 | E27: 20 | F27: 0.853 | H27: a | J27: 6 | K27: 7 | L27: 46175 | M27: 46115 | N27: 23.853 | Q27: 0
B28: L27 | C28: 19 | D28: 0.388 | E28: 17 | F28: -1.612 | H28: a | J28: 6 | K28: 7 | L28: 46175 | M28: 46082 | N28: 17.388 | Q28: 0
B29: L28 | C29: 13 | D29: 0.406 | E29: 13 | F29: 0.406 | H29: a | J29: 6 | K29: 7 | L29: 46175 | M29: 46054 | N29: 13.406 | Q29: 0
C30: 25.5 | D30: 25.5 | E30: 0 | F30: 0 | H30: v | J30: 6 | K30: 7 | L30: 46175 | M30: 46114 | N30: 25.5 | O30: x | Q30: 0
B31: L29 | E31: 0 | F31: 0 | J31: 6 | K31: 7 | L31: 46175 | M31: 46054 | N31: 0 | O31: x | Q31: 0
B32: L30 | C32: 25.5 | D32: 13.027 | E32: 13 | F32: 0.527 | H32: v | J32: 6 | K32: 7 | L32: 46175 | M32: 46114 | N32: 26.027 | Q32: 0
B33: L31 | C33: 25.5 | D33: 0.74 | E33: 24.5 | F33: -0.26 | H33: v | J33: 6 | K33: 7 | L33: 46175 | M33: 46114 | N33: 25.24 | Q33: 0
B34: L32 | C34: 16 | D34: 2.043 | E34: 15 | F34: 1.043 | H34: a | J34: 6 | K34: 7 | L34: 46175 | M34: 46082 | N34: 17.043 | Q34: 0
B35: L33 | C35: 25.5 | D35: 10.737 | E35: 13 | F35: -1.763 | H35: v | J35: 6 | K35: 7 | L35: 46175 | M35: 46144 | N35: 23.737 | Q35: 0
B36: L34 | C36: 18 | D36: 0.546 | E36: 17 | F36: -0.454 | H36: a | J36: 6 | K36: 7 | L36: 46175 | M36: 46114 | N36: 17.546 | Q36: 0
B37: L35 | C37: 9 | E37: 9 | F37: 0 | J37: 6 | K37: 0 | L37: 0-6 | N37: 9 | Q37: 0
B38: L36 | E38: 0 | F38: 0 | H38: v | J38: 6 | K38: 7 | L38: 46174 | M38: 46054 | N38: 0 | Q38: 0
B39: L37 | E39: 1 | F39: 1 | J39: 6 | K39: 0 | L39: 0-6 | M39: 0-8 | N39: 1 | Q39: 0
B40: L38 | C40: 25.5 | D40: 1.609 | E40: 24 | F40: 0.109 | H40: v | J40: 6 | K40: 7 | L40: 46175 | M40: 46114 | N40: 25.609 | Q40: 0
...

Sheet ZWL
A1: A-M | B1: 1
A2: Stunde | B2: Mo | C2: Di | D2: Mi | E2: Do | F2: Fr
A3: 1
A4: 2
A5: 3
A6: 4
A7: 5
A8: 6 | C8: -3
A9: 7 | C9: -3
A10: 8 | C10: -3
A11: 9 | C11: -3
A12: 10 | C12: -3
A13: 11 | C13: -3
A16: Ar | B16: 1
A17: Stunde | B17: Mo | C17: Di | D17: Mi | E17: Do | F17: Fr
A18: 1
A19: 2
A20: 3
A21: 4
A22: 5
A23: 6
A24: 7
A25: 8
A26: 9
A27: 10
A28: 11
A31: Ba | B31: 1
A32: Stunde | B32: Mo | C32: Di | D32: Mi | E32: Do | F32: Fr
A33: 1 | C33: -3
A34: 2 | C34: -3
A35: 3 | C35: -3
A36: 4 | C36: -3
A37: 5 | C37: -3
A38: 6 | C38: -3
A39: 7 | E39: -2 | F39: -2
A40: 8 | E40: -2 | F40: -2
A41: 9 | E41: -2 | F41: -2
A42: 10 | E42: -2 | F42: -2
A43: 11 | E43: -2 | F43: -2
A46: Bar
...

Sheet ZWK
A1: 05A
A2: Stunde | B2: Mo | C2: Di | D2: Mi | E2: Do | F2: Fr
A3: 1
A4: 2
A5: 3
A6: 4
A7: 5
A8: 6
A9: 7 | B9: -3 | D9: -3 | E9: -3 | F9: -3
A10: 8 | B10: -3 | C10: -3 | D10: -3 | E10: -3 | F10: -3
A11: 9 | B11: -3 | C11: -3 | D11: -3 | E11: -3 | F11: -3
A12: 10 | B12: -3 | C12: -3 | D12: -3 | E12: -3 | F12: -3
A13: 11 | B13: -3 | C13: -3 | D13: -3 | E13: -3 | F13: -3
A16: 05B
A17: Stunde | B17: Mo | C17: Di | D17: Mi | E17: Do | F17: Fr
A18: 1
A19: 2
A20: 3
A21: 4
A22: 5
A23: 6
A24: 7 | B24: -3 | D24: -3 | E24: -3 | F24: -3
A25: 8 | B25: -3 | C25: -3 | D25: -3 | E25: -3 | F25: -3
A26: 9 | B26: -3 | C26: -3 | D26: -3 | E26: -3 | F26: -3
A27: 10 | B27: -3 | C27: -3 | D27: -3 | E27: -3 | F27: -3
A28: 11 | B28: -3 | C28: -3 | D28: -3 | E28: -3 | F28: -3
A31: 05C
A32: Stunde | B32: Mo | C32: Di | D32: Mi | E32: Do | F32: Fr
A33: 1
A34: 2
A35: 3
A36: 4
A37: 5
A38: 6
A39: 7 | B39: -3 | D39: -3 | E39: -3 | F39: -3
A40: 8 | B40: -3 | C40: -3 | D40: -3 | E40: -3 | F40: -3
A41: 9 | B41: -3 | C41: -3 | D41: -3 | E41: -3 | F41: -3
A42: 10 | B42: -3 | C42: -3 | D42: -3 | E42: -3 | F42: -3
A43: 11 | B43: -3 | C43: -3 | D43: -3 | E43: -3 | F43: -3
A46: 05D
...

Sheet Diag
A1: Lehrer | B1: oT_1 | K1: oT_2 | T1: Plan
A2: Lehrer | B2: Hohlstd. | C2: Soll min | D2: Soll max | E2: DoppelHohl | F2: DreiHohl | G2: Max Folge | H2: Folge max | I2: Einzelstd. | K2: Hohlstd. | L2: Soll min | M2: Soll max | N2: DoppelHohl | O2: DreiHohl | P2: Max Folge | Q2: Folge max | R2: Einzelstd. | T2: Hohlstd. | U2: Soll min | V2: Soll max | W2: DoppelHohl | X2: DreiHohl | Y2: Max Folge | Z2: Folge max | AA2: Einzelstd.
A3: A-M | B3: 4 | C3: – | D3: – | E3: 0 | F3: 1 | G3: 4 | H3: – | I3: 1 | K3: 4 | L3: – | M3: – | N3: 0 | O3: 1 | P3: 4 | Q3: – | R3: 1 | T3: 2 | U3: – | V3: – | W3: 1 | X3: 0 | Y3: 2 | Z3: – | AA3: 0
A4: An | B4: 0 | C4: – | D4: – | E4: 0 | F4: 0 | G4: 2 | H4: – | I4: 1 | K4: 0 | L4: – | M4: – | N4: 0 | O4: 0 | P4: 2 | Q4: – | R4: 1 | T4: 0 | U4: – | V4: – | W4: 0 | X4: 0 | Y4: 2 | Z4: – | AA4: 1
A5: Ar | B5: 0 | C5: – | D5: – | E5: 0 | F5: 0 | G5: 3 | H5: – | I5: 1 | K5: 0 | L5: – | M5: – | N5: 0 | O5: 0 | P5: 3 | Q5: – | R5: 1 | T5: 2 | U5: – | V5: – | W5: 1 | X5: 0 | Y5: 2 | Z5: – | AA5: 0
A6: Ba | B6: 0 | C6: – | D6: – | E6: 0 | F6: 0 | G6: 2 | H6: – | I6: 1 | K6: 0 | L6: – | M6: – | N6: 0 | O6: 0 | P6: 2 | Q6: – | R6: 1 | T6: 0 | U6: – | V6: – | W6: 0 | X6: 0 | Y6: 2 | Z6: – | AA6: 1
A7: Bar | B7: 2 | C7: – | D7: – | E7: 1 | F7: 0 | G7: 4 | H7: – | I7: 0 | K7: 2 | L7: – | M7: – | N7: 1 | O7: 0 | P7: 4 | Q7: – | R7: 0 | T7: 3 | U7: – | V7: – | W7: 1 | X7: 0 | Y7: 3 | Z7: – | AA7: 0
A8: Bch | B8: 6 | C8: – | D8: – | E8: 0 | F8: 1 | G8: 2 | H8: – | I8: 0 | K8: 6 | L8: – | M8: – | N8: 0 | O8: 1 | P8: 2 | Q8: – | R8: 0 | T8: 2 | U8: – | V8: – | W8: 1 | X8: 0 | Y8: 2 | Z8: – | AA8: 0
A9: Ber | B9: 4 | C9: – | D9: – | E9: 0 | F9: 1 | G9: 3 | H9: – | I9: 0 | K9: 4 | L9: – | M9: – | N9: 0 | O9: 1 | P9: 3 | Q9: – | R9: 1 | T9: 0 | U9: – | V9: – | W9: 0 | X9: 0 | Y9: 2 | Z9: – | AA9: 1
A10: Bg | B10: 5 | C10: – | D10: – | E10: 0 | F10: 1 | G10: 4 | H10: – | I10: 0 | K10: 5 | L10: – | M10: – | N10: 0 | O10: 1 | P10: 4 | Q10: – | R10: 0 | T10: 5 | U10: – | V10: – | W10: 1 | X10: 1 | Y10: 3 | Z10: – | AA10: 1
A11: Bl | B11: 4 | C11: – | D11: – | E11: 0 | F11: 0 | G11: 6 | H11: – | I11: 0 | K11: 4 | L11: – | M11: – | N11: 0 | O11: 0 | P11: 6 | Q11: – | R11: 0 | T11: 4 | U11: – | V11: – | W11: 0 | X11: 1 | Y11: 4 | Z11: – | AA11: 0
A12: Br | B12: 5 | C12: – | D12: – | E12: 2 | F12: 0 | G12: 3 | H12: – | I12: 0 | K12: 5 | L12: – | M12: – | N12: 2 | O12: 0 | P12: 3 | Q12: – | R12: 0 | T12: 2 | U12: – | V12: – | W12: 0 | X12: 0 | Y12: 5 | Z12: – | AA12: 2
A13: Bra | B13: 4 | C13: – | D13: – | E13: 0 | F13: 1 | G13: 2 | H13: – | I13: 1 | K13: 4 | L13: – | M13: – | N13: 0 | O13: 1 | P13: 2 | Q13: – | R13: 1 | T13: 4 | U13: – | V13: – | W13: 0 | X13: 1 | Y13: 3 | Z13: – | AA13: 0
A14: Brb | B14: 1 | C14: – | D14: – | E14: 0 | F14: 0 | G14: 2 | H14: – | I14: 1 | K14: 1 | L14: – | M14: – | N14: 0 | O14: 0 | P14: 2 | Q14: – | R14: 1 | T14: 0 | U14: – | V14: – | W14: 0 | X14: 0 | Y14: 2 | Z14: – | AA14: 1
... A75: Ya | B75: 2 | C75: – | D75: – | E75: 1 | F75: 0 | G75: 2 | H75: – | I75: 2 | K75: 2 | L75: – | M75: – | N75: 1 | O75: 0 | P75: 2 | Q75: – | R75: 2 | T75: 4 | U75: – | V75: – | W75: 0 | X75: 1 | Y75: 2 | Z75: – | AA75: 2
A76: Summe | B76: 165 | E76: 18 | F76: 19 | I76: 49 | K76: 167 | N76: 16 | O76: 20 | R76: 49 | T76: 110 | W76: 10 | X76: 18 | AA76: 50

Sheet Lös
A1: WTag | B1: Stunde | C1: oT_1 | D1: oT_2 | E1: Plan | F1: oT_1v | G1: OhneTausch_1_verbessert | H1: UNrPlan
A2: Mo | B2: 1 | C2: 1464, 1388, 1327, 232 | D2: 1464, 1388, 1327, 232 | E2: 1505, 1400, 1367, 232 | F2: 1505, 1426, 1325, 232 | G2: 1505, 1400, 1367, 232 | H2: 1367, 1400, 1505, 232
A3: Mo | B3: 2 | C3: 1464, 1396, 1327 | D3: 1464, 1396, 1327 | E3: 1505, 1400, 1367 | F3: 721, 1385, 1361 | G3: 1505, 1400, 1367 | H3: 1367, 1400, 1505
A4: Mo | B4: 3 | C4: 1572, 1385, 1311 | D4: 1572, 1385, 1311 | E4: 1475, 1385, 1327 | F4: 755, 87, 1464, 1400, 1311 | G4: 573, 1475, 1385, 1327 | H4: 1327, 1385, 1475, 154
A5: Mo | B5: 4 | C5: 1572, 1385, 1311 | D5: 1572, 1385, 1311 | E5: 1475, 1385, 1327 | F5: 1403, 1313 | G5: 721, 1475, 1385, 1327 | H5: 1327, 1385, 1475, 154
A6: Mo | B6: 5 | C6: 755, 1550, 1429, 1353 | D6: 755, 1550, 1429, 1353 | E6: 1517, 1432, 1357 | F6: 87, 1400, 1311 | G6: 55, 1517, 1432, 1357 | H6: 1357, 1432, 1517
A7: Mo | B7: 6 | C7: 1550, 1429, 1357 | D7: 1550, 1429, 1357 | E7: 1473, 1426, 1325 | F7: 1478, 1313 | G7: 755, 1473, 1426, 1325 | H7: 1325, 1426, 1473
A8: Mo | B8: 7 | C8: 1525, 1440, 1375 | D8: 1525, 1440, 1375 | E8: 1473, 1396, 1325 | F8: 1493, 1432 | G8: 1473, 1396, 1325 | H8: 1325, 1396, 1473
A9: Mo | B9: 8 | C9: 1739, 1566, 1092, 1740, 1339 | D9: 1739, 1566, 1092, 1740, 1339 | E9: 1739, 1566, 1092, 1740, 1339 | F9: 1739, 1566, 1092, 1740, 1339 | G9: 1739, 1566, 1092, 1740, 1339 | H9: 1339, 1740, 1092, 1566, 1739
A10: Mo | B10: 9 | C10: 1739, 1566, 1092, 1740, 1339 | D10: 1739, 1566, 1092, 1740, 1339 | E10: 1739, 1566, 1092, 1740, 1339 | F10: 1739, 1566, 1092, 1740, 1339 | G10: 1739, 1566, 1092, 1740, 1339 | H10: 1339, 1740, 1092, 1566, 1739
A11: Mo | B11: 10 | F11: 1475, 1380, 1319
A12: Mo | B12: 11 | F12: 1480, 1376
A13: Di | B13: 1 | C13: 1211, 1510, 1403, 1367, 83 | D13: 1211, 87, 1510, 1403, 1367, 83 | E13: 1211, 1478, 1449, 1359, 83 | F13: 1211, 1473, 1367, 83 | G13: 1211, 1478, 1449, 1359, 83 | H13: 1211, 1359, 1449, 1478, 83
A14: Di | B14: 2 | C14: 87, 573, 1468, 1376, 1367 | D14: 87, 573, 1468, 1376, 1367 | E14: 1463, 1429, 1311 | F14: 755, 1489, 1367 | G14: 721, 1463, 1429, 1311 | H14: 1311, 1429, 1463
A15: Di | B15: 3 | C15: 755, 1473, 1376, 1319 | D15: 755, 1473, 1376, 1319 | E15: 1727, 1463, 1429, 1311 | F15: 1440, 1315 | G15: 1727, 1463, 1429, 1311 | H15: 1727, 1311, 1429, 1463, 24
A16: Di | B16: 4 | C16: 1473, 1449, 1319 | D16: 1473, 1449, 1319 | E16: 1488, 1380, 1355 | F16: 1475, 1384, 1331 | G16: 755, 1488, 1380, 1355 | H16: 1355, 1380, 1488, 24
A17: Di | B17: 5 | C17: 1727, 1480, 1392, 1311 | D17: 1727, 1480, 1392, 1311 | E17: 1555, 1435, 1313 | F17: 1406, 1327 | G17: 87, 1555, 1435, 1313 | H17: 1313, 1435, 1555, 223
A18: Di | B18: 6 | C18: 721, 1498, 1392, 1311 | D18: 721, 1498, 1392, 1311 | E18: 1498, 1435, 1313 | F18: 1555, 1406, 1327 | G18: 1498, 1435, 1313 | H18: 1313, 1435, 1498, 223
A19: Di | B19: 7 | C19: 1733, 1488, 1426, 1363 | D19: 1733, 1488, 1426, 1363 | F19: 1733, 1388 | G19: 1733, 1525, 1403, 1363
A20: Di | B20: 8 | C20: 1650, 904, 1462, 1341 | D20: 1650, 904, 1462, 1341 | E20: 1341 | F20: 1650, 904, 1462, 1341 | G20: 1650, 904, 1462, 1341 | H20: 1341
A21: Di | B21: 9 | C21: 1650, 904, 1462, 1341 | D21: 1650, 904, 1462, 1341 | E21: 1341 | F21: 1650, 904, 1462, 1341 | G21: 1650, 904, 1462, 1341 | H21: 1341
A22: Di | B22: 10 | F22: 1505, 1385
A23: Di | B23: 11 | F23: 1510, 1389, 1373
A24: Mi | B24: 1 | C24: 1727, 1483, 1435, 1325, 83 | D24: 1727, 1483, 1435, 1325, 83 | E24: 1727, 1489, 1384, 1319, 83 | F24: 1727, 1483, 1435, 1329, 83 | G24: 1727, 1489, 1384, 1319, 83 | H24: 1727, 1319, 1384, 1489, 83
A25: Mi | B25: 2 | C25: 1483, 1435, 1325 | D25: 1483, 1435, 1325 | E25: 1489, 1384, 1319 | F25: 1483, 1435, 1329 | G25: 1489, 1384, 1319 | H25: 1319, 1384, 1489
A26: Mi | B26: 3 | C26: 721, 1499, 1389, 1331 | D26: 721, 1499, 1389, 1331 | E26: 1211, 1499, 1393, 1351 | F26: 87, 1489, 1397 | G26: 1211, 1499, 1393, 1351 | H26: 1211, 1351, 1393, 1499
A27: Mi | B27: 4 | C27: 569, 1469, 1406, 1347 | D27: 569, 1469, 1406, 1347 | E27: 1572, 1393, 1315 | F27: 721, 1488, 1422 | G27: 1572, 1393, 1315 | H27: 1315, 1393, 1572
A28: Mi | B28: 5 | C28: 55, 1463, 1406, 1323 | D28: 55, 1463, 1406, 1323 | E28: 1572, 1406, 1315 | F28: 1393, 1317 | G28: 1572, 1406, 1315 | H28: 1315, 1406, 1572, 1110, 1193, 3
A29: Mi | B29: 6 | C29: 1211, 1463, 1432, 1323 | D29: 1211, 1463, 1432, 1323 | E29: 1468, 1406, 1331 | F29: 55, 1422, 1311 | G29: 1468, 1406, 1331 | H29: 1331, 1406, 1468, 1110, 1193, 3
A30: Mi | B30: 7 | C30: 1517, 1397, 1351 | D30: 1517, 1397, 1351 | E30: 1480, 1440, 1321 | F30: 1445 | G30: 1480, 1440, 1321 | H30: 1321, 1440, 1480
A31: Mi | B31: 8 | C31: 1361 | D31: 1361 | E31: 1321 | F31: 1393, 1351 | G31: 1321 | H31: 1321
A32: Mi | B32: 9 | F32: 1494, 1396, 1311
A33: Mi | B33: 10 | F33: 1464, 1445, 1347
A34: Mi | B34: 11 | F34: 1469, 1449, 1315
A35: Do | B35: 1 | C35: 87, 1493, 1406, 1313, 156 | D35: 87, 1505, 1406, 1313, 156 | E35: 1510, 1411, 1375, 156 | F35: 1473, 1406, 156 | G35: 1510, 1411, 1375, 156 | H35: 1375, 1411, 1510, 110, 156
A36: Do | B36: 2 | C36: 87, 1493, 1406, 1313 | D36: 1505, 1406, 1313 | E36: 1494, 1388, 1311 | F36: 573, 1550, 1406 | G36: 1494, 1388, 1311 | H36: 1311, 1388, 1494, 110, 18
A37: Do | B37: 3 | C37: 569, 1494, 1384, 1317 | D37: 569, 1494, 1384, 1317 | E37: 1494, 1392, 1311 | F37: 569, 1550, 1411 | G37: 569, 1494, 1392, 1311 | H37: 1311, 1392, 1494, 118, 18
A38: Do | B38: 4 | C38: 569, 1494, 1384, 1317 | D38: 569, 1494, 1384, 1317 | E38: 1483, 1392, 1329 | F38: 55, 1517 | G38: 569, 1483, 1392, 1329 | H38: 1329, 1392, 1483, 159, 118
A39: Do | B39: 5 | C39: 1505, 1400, 1315 | D39: 1489, 1400, 1315 | E39: 1483, 1445, 1329 | F39: 1572, 1392, 1313 | G39: 1483, 1445, 1329 | H39: 1329, 1445, 1483, 1181, 159
A40: Do | B40: 6 | C40: 1505, 1400, 1315 | D40: 1489, 1400, 1315 | E40: 1464, 1445, 1347 | F40: 1572, 1392, 1313 | G40: 1464, 1445, 1347 | H40: 1347, 1445, 1464, 1181
...

Sheet Rank
A1: Plan | B1: Label | C1: Qualität | D1: frühe Doppel | E1: späte Doppel | F1: päd. Einheiten spät | G1: Hohlstunden | H1: Doppelhohlstunden | I1: Dreifachhohlstunden | J1: Einzelstunden | K1: späte LK-Stunden | L1: Hauptfach zu spät | M1: Details späte päd. Einheiten
A2: 1 | B2: OhneTausch_1 | C2: -5331 | D2: 35 | E2: 18 | F2: 13 | G2: 166 | H2: 16 | I2: 22 | J2: 47 | K2: 0 | L2: 0 | M2: EF | UNr 1520 | GK03 EF | UNr 1650 | GK15 EF | UNr 1475 | GK10 EF | UNr 1464 | GK11 EF | UNr 1739 | GK14 Q1 | UNr 1376 | GK05 Q1 | UNr 1393 | GK02 Q1 | UNr 904 | GK10 Q1 | UNr 1092 | GK11 Q2 | UNr 1321 | GK04 Q2 | UNr 1313 | LK01 Q2 | UNr 1341 | GK13 Q2 | UNr 1740 | GK10
A3: 2 | B3: OhneTausch_2 | C3: -5038 | D3: 39 | E3: 14 | F3: 12 | G3: 153 | H3: 16 | I3: 20 | J3: 65 | K3: 1 | L3: 0 | M3: EF | UNr 1650 | GK15 EF | UNr 1464 | GK11 EF | UNr 1739 | GK14 Q1 | UNr 1400 | GK06 Q1 | UNr 1435 | LK02 Q1 | UNr 904 | GK10 Q1 | UNr 1092 | GK11 Q2 | UNr 1323 | GK05 Q2 | UNr 1311 | LK02 Q2 | UNr 1313 | LK01 Q2 | UNr 1341 | GK13 Q2 | UNr 1740 | GK10
A4: 3 | B4: UNrPlan | C4: -4455 | D4: 31 | E4: 17 | F4: 13 | G4: 110 | H4: 10 | I4: 18 | J4: 50 | K4: 0 | L4: 0 | M4: EF | UNr 1473 | GK05 EF | UNr 1520 | GK03 EF | UNr 1464 | GK11 EF | UNr 1739 | GK14 Q1 | UNr 1376 | GK05 Q1 | UNr 1435 | LK02 Q1 | UNr 1092 | GK11 Q1 | UNr 385 | GK10 Q2 | UNr 1325 | GK06 Q2 | UNr 1321 | GK04 Q2 | UNr 1317 | GK02 Q2 | UNr 1341 | GK13 Q2 | UNr 1740 | GK10

Sheet Verl

Sheet ChkFix
A1: Kategorie | B1: Tag | C1: Stunde | D1: UNr | E1: Lehrer/Klasse | F1: Fach/ZeilenText | G1: Details
A2: ✓ Keine Verletzungen gefunden

Sheet Tausch

Sheet Rang
A1: Plan | B1: Label | C1: Qualität | D1: frühe Doppel | E1: späte Doppel | F1: päd. Einheiten spät | G1: Hohlstunden | H1: Doppelhohlstunden | I1: Dreifachhohlstunden | J1: Einzelstunden | K1: späte LK-Stunden | L1: Hauptfach zu spät | M1: Details späte päd. Einheiten
A2: 1 | B2: oT_1 | C2: -4725 | D2: 38 | E2: 15 | F2: 13 | G2: 165 | H2: 18 | I2: 19 | J2: 49 | K2: 0 | L2: 0 | M2: EF | UNr 1489 | GK12 EF | UNr 1550 | GK09 EF | UNr 1650 | GK15 EF | UNr 1739 | GK14 Q1 | UNr 1429 | GK03 Q1 | UNr 1393 | GK02 Q1 | UNr 904 | GK10 Q1 | UNr 1092 | GK11 Q2 | UNr 1323 | GK05 Q2 | UNr 1329 | GK08 Q2 | UNr 1321 | GK04 Q2 | UNr 1341 | GK13 Q2 | UNr 1740 | GK10
A3: 2 | B3: oT_2 | C3: -4917 | D3: 38 | E3: 15 | F3: 14 | G3: 167 | H3: 16 | I3: 20 | J3: 49 | K3: 0 | L3: 0 | M3: EF | UNr 1493 | GK04 EF | UNr 1489 | GK12 EF | UNr 1550 | GK09 EF | UNr 1650 | GK15 EF | UNr 1739 | GK14 Q1 | UNr 1429 | GK03 Q1 | UNr 1393 | GK02 Q1 | UNr 904 | GK10 Q1 | UNr 1092 | GK11 Q2 | UNr 1323 | GK05 Q2 | UNr 1329 | GK08 Q2 | UNr 1321 | GK04 Q2 | UNr 1341 | GK13 Q2 | UNr 1740 | GK10
A4: 3 | B4: Plan | C4: -4455 | D4: 31 | E4: 17 | F4: 13 | G4: 110 | H4: 10 | I4: 18 | J4: 50 | K4: 0 | L4: 0 | M4: EF | UNr 1473 | GK05 EF | UNr 1520 | GK03 EF | UNr 1464 | GK11 EF | UNr 1739 | GK14 Q1 | UNr 1376 | GK05 Q1 | UNr 1435 | LK02 Q1 | UNr 1092 | GK11 Q1 | UNr 385 | GK10 Q2 | UNr 1325 | GK06 Q2 | UNr 1321 | GK04 Q2 | UNr 1317 | GK02 Q2 | UNr 1341 | GK13 Q2 | UNr 1740 | GK10
